Workbook

Sheet ガントチャート
A1: Phase | B1: WBS | C1: Sub-Task | D1: Action | E1: Owner | F1: Deliverable | G1: Status | H1: 10月 | I1: 11月 | J1: 12月 | K1: 1月 | L1: 2月 | M1: 3月 | N1: 4月 | O1: 5月 | P1: 6月
A2: オンボーディング フェーズ (10-11月) | B2: 1.1 | C2: 学習・認証 | D2: Prerequisites 認証完了 | E2: KC+ATH | F2: 認証バッジ | G2: 完了
B3: 1.1.1 | D3: Developer Learning Path 完了 | E3: KC+ATH | F3: 学習修了証 | G3: 完了
B4: 1.1.2 | D4: Knowledge Badge 取得 | E4: KC+ATH | F4: バッジ証明 | G4: 完了
B5: 1.2 | C5: 技術評価 | D5: Workbench 環境セットアップ | E5: KC+ATH | F5: 環境構築完了 | G5: 完了
B6: 1.2.1 | D6: API 機能調査（Document Translation等） | E6: KC+ATH | F6: KPMG_Workbench_API一覧 | G6: 完了
B7: 1.3 | C7: 課題対応 | D7: 手続上の障壁把握 | E7: KC+ATH | F7: 課題リスト | G7: 完了
B8: 1.3.1 | D8: APIアクセス課題解決（12/1完了） | E8: ATH | F8: 解決策ドキュメント | G8: 完了
B9: 1.3.2 | D9: Global WB Community ローンチ（11/13） | E9: ATH | F9: Community稼働 | G9: 完了
B10: 1.4 | C10: 報告・計画 | D10: Onboarding簡易パワポ作成 | E10: KC+ATH | F10: Onboarding簡易パワポ | G10: 完了
B11: 1.4.1 | D11: KC・ALH共同会議 | E11: KC+ATH | F11: N/A | G11: 完了
A12: 誰でも1週間で 迷いなく開始 (12-1月) | B12: 2.1 | C12: KC組タスク | D12: 残りAPIテスト完了（Document Translation等） | E12: KC | F12: テストレポート | G12: 未開始
B13: 2.1.1 | D13: APIテスト報告総括 | E13: KC | F13: 総括レポート | G13: 未開始
B14: 2.1.2 | D14: Cookbook基礎テンプレート整備 | E14: KC | F14: テンプレート | G14: 未開始
B15: 2.1.3 | D15: ATH組への技術サポート資料提供 | E15: KC | F15: 技術資料 | G15: 未開始
B16: 2.1.4 | D16: ATH組成果物Review | E16: KC | F16: Reviewレポート | G16: 未開始
B17: 2.1.5 | D17: Cookbook上級用例補充（2シナリオ） | E17: KC | F17: 上級用例 | G17: 未開始
B18: 2.1.6 | D18: Agentベストプラクティスドキュメント作成 | E18: KC | F18: ベストプラクティス | G18: 未開始
B19: 2.1.7 | D19: Phase 2 総括レポート | E19: KC | F19: 総括レポート | G19: 未開始
B20: 2.2 | C20: ATH組タスク | D20: KJ開発者Onboardingサイト設計 | E20: ATH | F20: 設計書 | G20: 未開始
B21: 2.2.1 | D21: Onboardingサイトフロントエンド開発 | E21: ATH | F21: フロントエンド | G21: 未開始
B22: 2.2.2 | D22: Onboardingサイトコンテンツ作成 | E22: ATH | F22: コンテンツ | G22: 未開始
B23: 2.2.3 | D23: Agent検証環境構築 | E23: ATH | F23: 環境構築 | G23: 未開始
B24: 2.2.4 | D24: API/Agent基礎検証テスト | E24: ATH | F24: テスト結果 | G24: 未開始
B25: 2.2.5 | D25: Cookbookコア用例作成（5シナリオ） | E25: ATH | F25: コア用例 | G25: 未開始
B26: 2.2.6 | D26: 開発者コミュニティプラットフォーム構築 | E26: ATH | F26: プラットフォーム | G26: 未開始
B27: 2.2.7 | D27: 開発者コミュニティ初期コンテンツ | E27: ATH | F27: 初期コンテンツ | G27: 未開始
B28: 2.2.8 | D28: Onboardingサイトローンチ＆テスト | E28: ATH | F28: サイト稼働 | G28: 未開始
B29: 2.2.9 | D29: 開発者コミュニティ正式ローンチ | E29: ATH | F29: コミュニティ稼働 | G29: 未開始
A30: 海外MF ナレッジ探索 (2-3月) | B30: 3.1 | C30: POC討論 | D30: POC項目テーマブレインストーミング | E30: KC+ATH | F30: テーマリスト | G30: 未開始
B31: 3.1.1 | D31: 関係者ニーズ・アイデア収集 | E31: ATH | F31: ニーズリスト | G31: 未開始
B32: 3.1.2 | D32: POC項目フィージビリティ初期評価 | E32: KC+ATH | F32: 評価結果 | G32: 未開始
B33: 3.1.3 | D33: POC項目リスト確定（2-3件） | E33: KC+ATH | F33: 確定リスト | G33: 未開始
B34: 3.2 | C34: 海外MF情報収集 | D34: US/UK/AU等MFのAgent開発事例収集 | E34: ATH | F34: 事例リスト | G34: 未開始
B35: 3.2.1 | D35: 海外MF技術ドキュメント翻訳整理 | E35: ATH | F35: 翻訳ドキュメント | G35: 未開始
B36: 3.2.2 | D36: ナレッジ再利用フレームワーク構築 | E36: ATH | F36: フレームワーク | G36: 未開始
B37: 3.2.3 | D37: 海外MF技術交流会議（2回） | E37: KC | F37: 会議記録 | G37: 未開始
B38: 3.2.4 | D38: 海外ソリューション実現可能性評価レポート | E38: KC | F38: 評価レポート | G38: 未開始
B39: 3.3 | C39: POC開始 | D39: POC項目A開始 | E39: ATH | F39: POC A進捗 | G39: 未開始
B40: 3.3.1 | D40: POC項目B開始 | E40: ATH | F40: POC B進捗 | G40: 未開始
...

Sheet KC組タスク
A1: Phase | B1: WBS | C1: Sub-Task | D1: Action | E1: Months | F1: Deliverable | G1: Status
A2: オンボーディング フェーズ (10-11月) | B2: 1.1 | C2: 学習・認証 | D2: Prerequisites 認証完了 | E2: 10月 | F2: 認証バッジ | G2: =VLOOKUP(B2,ガントチャート!$B$2:$G$54,6,FALSE) -> 完了
B3: 1.1.1 | D3: Developer Learning Path 完了 | E3: 10月, 11月 | F3: 学習修了証 | G3: =VLOOKUP(B3,ガントチャート!$B$2:$G$54,6,FALSE) -> 完了
B4: 1.1.2 | D4: Knowledge Badge 取得 | E4: 11月 | F4: バッジ証明 | G4: =VLOOKUP(B4,ガントチャート!$B$2:$G$54,6,FALSE) -> 完了
B5: 1.2 | C5: 技術評価 | D5: Workbench 環境セットアップ | E5: 10月 | F5: 環境構築完了 | G5: =VLOOKUP(B5,ガントチャート!$B$2:$G$54,6,FALSE) -> 完了
B6: 1.2.1 | D6: API 機能調査（Document Translation等） | E6: 10月, 11月 | F6: API調査レポート | G6: =VLOOKUP(B6,ガントチャート!$B$2:$G$54,6,FALSE) -> 完了
B7: 1.2.2 | D7: Agent 開発フレームワーク評価 | E7: 11月 | F7: 評価レポート | G7: =VLOOKUP(B7,ガントチャート!$B$2:$G$54,6,FALSE) -> #N/A
B8: 1.3 | C8: 課題対応 | D8: 手続上の障壁把握 | E8: 10月 | F8: 課題リスト | G8: =VLOOKUP(B8,ガントチャート!$B$2:$G$54,6,FALSE) -> 完了
B9: 1.3.1 | D9: APIアクセス課題解決（12/1完了） | E9: 11月 | F9: 解決策ドキュメント | G9: =VLOOKUP(B9,ガントチャート!$B$2:$G$54,6,FALSE) -> 完了
B10: 1.3.2 | D10: Global WB Community ローンチ（11/13） | E10: 11月 | F10: Community稼働 | G10: =VLOOKUP(B10,ガントチャート!$B$2:$G$54,6,FALSE) -> 完了
B11: 1.4 | C11: 報告・計画 | D11: 技術評価レポート作成 | E11: 11月 | F11: 評価レポート | G11: =VLOOKUP(B11,ガントチャート!$B$2:$G$54,6,FALSE) -> 完了
B12: 1.4.1 | D12: Phase 2 計画策定 | E12: 11月 | F12: 計画書 | G12: =VLOOKUP(B12,ガントチャート!$B$2:$G$54,6,FALSE) -> 完了
A13: 誰でも1週間で 迷いなく開始 (12-1月) | B13: 2.1 | C13: KC組タスク | D13: 残りAPIテスト完了（Document Translation等） | E13: 12月 | F13: テストレポート | G13: =VLOOKUP(B13,ガントチャート!$B$2:$G$54,6,FALSE) -> 未開始
B14: 2.1.1 | D14: APIテスト報告総括 | E14: 12月 | F14: 総括レポート | G14: =VLOOKUP(B14,ガントチャート!$B$2:$G$54,6,FALSE) -> 未開始
B15: 2.1.2 | D15: Cookbook基礎テンプレート整備 | E15: 12月 | F15: テンプレート | G15: =VLOOKUP(B15,ガントチャート!$B$2:$G$54,6,FALSE) -> 未開始
B16: 2.1.3 | D16: ATH組への技術サポート資料提供 | E16: 12月 | F16: 技術資料 | G16: =VLOOKUP(B16,ガントチャート!$B$2:$G$54,6,FALSE) -> 未開始
B17: 2.1.4 | D17: ATH組成果物Review | E17: 1月 | F17: Reviewレポート | G17: =VLOOKUP(B17,ガントチャート!$B$2:$G$54,6,FALSE) -> 未開始
B18: 2.1.5 | D18: Cookbook上級用例補充（2シナリオ） | E18: 1月 | F18: 上級用例 | G18: =VLOOKUP(B18,ガントチャート!$B$2:$G$54,6,FALSE) -> 未開始
B19: 2.1.6 | D19: Agentベストプラクティスドキュメント作成 | E19: 1月 | F19: ベストプラクティス | G19: =VLOOKUP(B19,ガントチャート!$B$2:$G$54,6,FALSE) -> 未開始
B20: 2.1.7 | D20: Phase 2 総括レポート | E20: 1月 | F20: 総括レポート | G20: =VLOOKUP(B20,ガントチャート!$B$2:$G$54,6,FALSE) -> 未開始
A21: 海外MF ナレッジ探索 (2-3月) | B21: 3.1 | C21: POC討論 | D21: POC項目テーマブレインストーミング | E21: 1月 | F21: テーマリスト | G21: =VLOOKUP(B21,ガントチャート!$B$2:$G$54,6,FALSE) -> 未開始
B22: 3.1.2 | D22: POC項目フィージビリティ初期評価 | E22: 1月 | F22: 評価結果 | G22: =VLOOKUP(B22,ガントチャート!$B$2:$G$54,6,FALSE) -> 未開始
B23: 3.1.3 | D23: POC項目リスト確定（2-3件） | E23: 1月 | F23: 確定リスト | G23: =VLOOKUP(B23,ガントチャート!$B$2:$G$54,6,FALSE) -> 未開始
B24: 3.2.3 | C24: 海外MF情報収集 | D24: 海外MF技術交流会議（2回） | E24: 2月 | F24: 会議記録 | G24: =VLOOKUP(B24,ガントチャート!$B$2:$G$54,6,FALSE) -> 未開始
B25: 3.2.4 | D25: 海外ソリューション実現可能性評価レポート | E25: 2月 | F25: 評価レポート | G25: =VLOOKUP(B25,ガントチャート!$B$2:$G$54,6,FALSE) -> 未開始
B26: 3.3.2 | C26: POC開始 | D26: POC技術サポート | E26: 3月 | F26: 技術サポート | G26: =VLOOKUP(B26,ガントチャート!$B$2:$G$54,6,FALSE) -> 未開始
B27: 3.3.3 | D27: POC中期レビュー | E27: 3月 | F27: 中期レビュー | G27: =VLOOKUP(B27,ガントチャート!$B$2:$G$54,6,FALSE) -> 未開始
A28: スピーディな プロダクトプロセス (4-6月) | B28: 4.2 | C28: 本番アプリ開発 | D28: 本番アプリアーキテクチャ設計Review | E28: 4月 | F28: 設計Review | G28: =VLOOKUP(B28,ガントチャート!$B$2:$G$54,6,FALSE) -> 未開始
B29: 4.2.3 | D29: セキュリティ・コンプライアンス審査 | E29: 4月 | F29: 審査結果 | G29: =VLOOKUP(B29,ガントチャート!$B$2:$G$54,6,FALSE) -> 未開始
B30: 4.3.3 | C30: リリース | D30: 最終発表承認 | E30: 5月 | F30: 承認完了 | G30: =VLOOKUP(B30,ガントチャート!$B$2:$G$54,6,FALSE) -> 未開始
B31: 4.4.1 | C31: プロセス確立 | D31: プロジェクト総括レポート | E31: 6月 | F31: 総括レポート | G31: =VLOOKUP(B31,ガントチャート!$B$2:$G$54,6,FALSE) -> 未開始

Sheet ATH組タスク
A1: Phase | B1: WBS | C1: Sub-Task | D1: Action | E1: Months | F1: Deliverable | G1: Status
A2: オンボーディング フェーズ (10-11月) | B2: 1.1 | C2: 学習・認証 | D2: Prerequisites 認証完了 | E2: 10月 | F2: 認証バッジ | G2: =VLOOKUP(B2,ガントチャート!$B$2:$G$54,6,FALSE) -> 完了
B3: 1.1.1 | D3: Developer Learning Path 完了 | E3: 10月, 11月 | F3: 学習修了証 | G3: =VLOOKUP(B3,ガントチャート!$B$2:$G$54,6,FALSE) -> 完了
B4: 1.1.2 | D4: Knowledge Badge 取得 | E4: 11月 | F4: バッジ証明 | G4: =VLOOKUP(B4,ガントチャート!$B$2:$G$54,6,FALSE) -> 完了
B5: 1.2 | C5: 技術評価 | D5: Workbench 環境セットアップ | E5: 10月 | F5: 環境構築完了 | G5: =VLOOKUP(B5,ガントチャート!$B$2:$G$54,6,FALSE) -> 完了
B6: 1.2.1 | D6: API 機能調査（Document Translation等） | E6: 10月, 11月 | F6: API調査レポート | G6: =VLOOKUP(B6,ガントチャート!$B$2:$G$54,6,FALSE) -> 完了
B7: 1.2.2 | D7: Agent 開発フレームワーク評価 | E7: 11月 | F7: 評価レポート | G7: =VLOOKUP(B7,ガントチャート!$B$2:$G$54,6,FALSE) -> #N/A
B8: 1.3 | C8: 課題対応 | D8: 手続上の障壁把握 | E8: 10月 | F8: 課題リスト | G8: =VLOOKUP(B8,ガントチャート!$B$2:$G$54,6,FALSE) -> 完了
B9: 1.3.1 | D9: APIアクセス課題解決（12/1完了） | E9: 11月 | F9: 解決策ドキュメント | G9: =VLOOKUP(B9,ガントチャート!$B$2:$G$54,6,FALSE) -> 完了
B10: 1.3.2 | D10: Global WB Community ローンチ（11/13） | E10: 11月 | F10: Community稼働 | G10: =VLOOKUP(B10,ガントチャート!$B$2:$G$54,6,FALSE) -> 完了
B11: 1.4 | C11: 報告・計画 | D11: 技術評価レポート作成 | E11: 11月 | F11: 評価レポート | G11: =VLOOKUP(B11,ガントチャート!$B$2:$G$54,6,FALSE) -> 完了
B12: 1.4.1 | D12: Phase 2 計画策定 | E12: 11月 | F12: 計画書 | G12: =VLOOKUP(B12,ガントチャート!$B$2:$G$54,6,FALSE) -> 完了
A13: 誰でも1週間で 迷いなく開始 (12-1月) | B13: 2.2 | C13: ATH組タスク | D13: KJ開発者Onboardingサイト設計 | E13: 12月 | F13: 設計書 | G13: =VLOOKUP(B13,ガントチャート!$B$2:$G$54,6,FALSE) -> 未開始
B14: 2.2.1 | D14: Onboardingサイトフロントエンド開発 | E14: 12月 | F14: フロントエンド | G14: =VLOOKUP(B14,ガントチャート!$B$2:$G$54,6,FALSE) -> 未開始
B15: 2.2.2 | D15: Onboardingサイトコンテンツ作成 | E15: 1月 | F15: コンテンツ | G15: =VLOOKUP(B15,ガントチャート!$B$2:$G$54,6,FALSE) -> 未開始
B16: 2.2.3 | D16: Agent検証環境構築 | E16: 12月 | F16: 環境構築 | G16: =VLOOKUP(B16,ガントチャート!$B$2:$G$54,6,FALSE) -> 未開始
B17: 2.2.4 | D17: API/Agent基礎検証テスト | E17: 12月 | F17: テスト結果 | G17: =VLOOKUP(B17,ガントチャート!$B$2:$G$54,6,FALSE) -> 未開始
B18: 2.2.5 | D18: Cookbookコア用例作成（5シナリオ） | E18: 1月 | F18: コア用例 | G18: =VLOOKUP(B18,ガントチャート!$B$2:$G$54,6,FALSE) -> 未開始
B19: 2.2.6 | D19: 開発者コミュニティプラットフォーム構築 | E19: 1月 | F19: プラットフォーム | G19: =VLOOKUP(B19,ガントチャート!$B$2:$G$54,6,FALSE) -> 未開始
B20: 2.2.7 | D20: 開発者コミュニティ初期コンテンツ | E20: 1月 | F20: 初期コンテンツ | G20: =VLOOKUP(B20,ガントチャート!$B$2:$G$54,6,FALSE) -> 未開始
B21: 2.2.8 | D21: Onboardingサイトローンチ＆テスト | E21: 1月 | F21: サイト稼働 | G21: =VLOOKUP(B21,ガントチャート!$B$2:$G$54,6,FALSE) -> 未開始
B22: 2.2.9 | D22: 開発者コミュニティ正式ローンチ | E22: 1月 | F22: コミュニティ稼働 | G22: =VLOOKUP(B22,ガントチャート!$B$2:$G$54,6,FALSE) -> 未開始
A23: 海外MF ナレッジ探索 (2-3月) | B23: 3.1 | C23: POC討論 | D23: POC項目テーマブレインストーミング | E23: 1月 | F23: テーマリスト | G23: =VLOOKUP(B23,ガントチャート!$B$2:$G$54,6,FALSE) -> 未開始
B24: 3.1.1 | D24: 関係者ニーズ・アイデア収集 | E24: 1月 | F24: ニーズリスト | G24: =VLOOKUP(B24,ガントチャート!$B$2:$G$54,6,FALSE) -> 未開始
B25: 3.1.2 | D25: POC項目フィージビリティ初期評価 | E25: 1月 | F25: 評価結果 | G25: =VLOOKUP(B25,ガントチャート!$B$2:$G$54,6,FALSE) -> 未開始
B26: 3.1.3 | D26: POC項目リスト確定（2-3件） | E26: 1月 | F26: 確定リスト | G26: =VLOOKUP(B26,ガントチャート!$B$2:$G$54,6,FALSE) -> 未開始
B27: 3.2 | C27: 海外MF情報収集 | D27: US/UK/AU等MFのAgent開発事例収集 | E27: 2月 | F27: 事例リスト | G27: =VLOOKUP(B27,ガントチャート!$B$2:$G$54,6,FALSE) -> 未開始
B28: 3.2.1 | D28: 海外MF技術ドキュメント翻訳整理 | E28: 2月 | F28: 翻訳ドキュメント | G28: =VLOOKUP(B28,ガントチャート!$B$2:$G$54,6,FALSE) -> 未開始
B29: 3.2.2 | D29: ナレッジ再利用フレームワーク構築 | E29: 2月 | F29: フレームワーク | G29: =VLOOKUP(B29,ガントチャート!$B$2:$G$54,6,FALSE) -> 未開始
B30: 3.3 | C30: POC開始 | D30: POC項目A開始 | E30: 3月 | F30: POC A進捗 | G30: =VLOOKUP(B30,ガントチャート!$B$2:$G$54,6,FALSE) -> 未開始
B31: 3.3.1 | D31: POC項目B開始 | E31: 3月 | F31: POC B進捗 | G31: =VLOOKUP(B31,ガントチャート!$B$2:$G$54,6,FALSE) -> 未開始
A32: スピーディな プロダクトプロセス (4-6月) | B32: 4.1 | C32: POC完成 | D32: POC項目A完成＆評価 | E32: 3月, 4月 | F32: POC A完成 | G32: =VLOOKUP(B32,ガントチャート!$B$2:$G$54,6,FALSE) -> 未開始
B33: 4.1.1 | D33: POC項目B完成＆評価 | E33: 3月, 4月 | F33: POC B完成 | G33: =VLOOKUP(B33,ガントチャート!$B$2:$G$54,6,FALSE) -> 未開始
B34: 4.2.1 | C34: 本番アプリ開発 | D34: 本番アプリ開発（項目A） | E34: 4月, 5月 | F34: アプリA | G34: =VLOOKUP(B34,ガントチャート!$B$2:$G$54,6,FALSE) -> 未開始
B35: 4.2.2 | D35: 本番アプリ開発（項目B） | E35: 4月, 5月 | F35: アプリB | G35: =VLOOKUP(B35,ガントチャート!$B$2:$G$54,6,FALSE) -> 未開始
B36: 4.3 | C36: リリース | D36: UATテスト | E36: 5月 | F36: テスト結果 | G36: =VLOOKUP(B36,ガントチャート!$B$2:$G$54,6,FALSE) -> 未開始
B37: 4.3.1 | D37: 本番リリース準備 | E37: 5月 | F37: リリース準備 | G37: =VLOOKUP(B37,ガントチャート!$B$2:$G$54,6,FALSE) -> 未開始
B38: 4.3.2 | D38: 本番リリース＆監視 | E38: 5月, 6月 | F38: リリース完了 | G38: =VLOOKUP(B38,ガントチャート!$B$2:$G$54,6,FALSE) -> 未開始
B39: 4.4 | C39: プロセス確立 | D39: 新プロセスドキュメント化 | E39: 6月 | F39: プロセスドキュメント | G39: =VLOOKUP(B39,ガントチャート!$B$2:$G$54,6,FALSE) -> 未開始

Sheet 休暇カレンダー
A1: カレンダービュー | R1: 2024-2025 年末年始休暇カレンダー
A3: 2024年12月 | J3: 2025年1月 | R3: 組織 | S3: 開始日 | T3: 終了日
A4: 月 | B4: 火 | C4: 水 | D4: 木 | E4: 金 | F4: 土 | G4: 日 | J4: 月 | K4: 火 | L4: 水 | M4: 木 | N4: 金 | O4: 土 | P4: 日 | R4: KC | S4: 2024-12-24 | T4: 2025-01-05
G5: 1 | L5: 1 | M5: 2 | N5: 3 | O5: 4 | P5: 5 | R5: ATH | S5: 2024-12-28 | T5: 2025-01-05
A6: 2 | B6: 3 | C6: 4 | D6: 5 | E6: 6 | F6: 7 | G6: 8 | J6: 6 | K6: 7 | L6: 8 | M6: 9 | N6: 10 | O6: 11 | P6: 12
A7: 9 | B7: 10 | C7: 11 | D7: 12 | E7: 13 | F7: 14 | G7: 15 | J7: 13 | K7: 14 | L7: 15 | M7: 16 | N7: 17 | O7: 18 | P7: 19
A8: 16 | B8: 17 | C8: 18 | D8: 19 | E8: 20 | F8: 21 | G8: 22 | J8: 20 | K8: 21 | L8: 22 | M8: 23 | N8: 24 | O8: 25 | P8: 26
A9: 23 | B9: 24 | C9: 25 | D9: 26 | E9: 27 | F9: 28 | G9: 29 | J9: 27 | K9: 28 | L9: 29 | M9: 30 | N9: 31
A10: 30 | B10: 31
A12: 凡例:
A13: KC休暇(Ma)
A14: ATH休暇
A15: 両方休暇

Sheet マイルストーン
A1: マイルストーン | B1: 予定日 | C1: 実績日 | D1: 成果物 | E1: ステータス
A2: Phase 1 開始 | B2: 2024-10-01 | D2: オンボーディング開始 | E2: 未開始
A3: Prerequisites認証完了 | B3: 2024-10-31 | D3: 認証バッジ | E3: 未開始
A4: 技術評価レポート完成 | B4: 2024-11-30 | D4: 評価レポート | E4: 未開始
A5: Phase 2 開始 | B5: 2024-12-01 | D5: チーム拡大 | E5: 未開始
A6: KC組休暇開始 | B6: 2024-12-24 | D6: 引継ぎ完了 | E6: 未開始
A7: ATH組休暇開始 | B7: 2024-12-28 | D7: - | E7: 未開始
A8: 全員復帰 | B8: 2025-01-06 | D8: 開発再開 | E8: 未開始
A9: Onboardingサイト公開 | B9: 2025-01-31 | D9: サイト稼働 | E9: 未開始
A10: 開発者コミュニティ公開 | B10: 2025-01-31 | D10: コミュニティ稼働 | E10: 未開始
A11: Phase 3 開始 | B11: 2025-02-01 | D11: 海外MF探索開始 | E11: 未開始
A12: POC項目確定 | B12: 2025-01-31 | D12: 確定リスト | E12: 未開始
A13: POC開始 | B13: 2025-03-01 | D13: POC開発開始 | E13: 未開始
... A18: プロジェクト完了 | B18: 2025-06-30 | D18: 総括レポート | E18: 未開始
